cache_run_c_code = 'Test does not build: Traceback (most recent call last):\n  File "/home/pradeepkumar/Desktop/ns3-plc-with-gnosis/ns-3.15/.waf-1.6.11-30618c54883417962c38f5d395f83584/waflib/Tools/c_config.py", line 445, in run_c_code\n    bld.compile()\n  File "/home/pradeepkumar/Desktop/ns3-plc-with-gnosis/ns-3.15/.waf-1.6.11-30618c54883417962c38f5d395f83584/waflib/Build.py", line 190, in compile\n    raise Errors.BuildError(self.producer.error)\nBuildError: Build failed\n -> task in \'testprog\' failed (exit status 1): \n\t{task 140228517488528: cxx test.cpp -> test.cpp.1.o}\n[\'/usr/bin/g++\', \'-std=c++0x\', \'-fno-strict-aliasing\', \'-fwrapv\', \'-fdebug-prefix-map=/build/python2.7-gnDdqE/python2.7-2.7.17=.\', \'-fstack-protector-strong\', \'-fno-strict-aliasing\', \'-fno-strict-aliasing\', \'-fdebug-prefix-map=/build/python2.7-gnDdqE/python2.7-2.7.17=.\', \'-fstack-protector-strong\', \'-fwrapv\', \'-I/usr/include/python2.7\', \'-I/usr/include/x86_64-linux-gnu/python2.7\', \'-DNS3_ASSERT_ENABLE\', \'-DNS3_LOG_ENABLE\', \'-DPYTHONDIR="/usr/local/lib/python2.7/dist-packages"\', \'-DPYTHONARCHDIR="/usr/local/lib/python2.7/dist-packages"\', \'-DHAVE_PYEMBED=1\', \'-DNDEBUG\', \'-D_FORTIFY_SOURCE=2\', \'-D_FORTIFY_SOURCE=2\', \'-DNDEBUG\', \'../test.cpp\', \'-c\', \'-o\', \'test.cpp.1.o\']\n'
